<?xml version="1.0"?>
<robot xmlns:xacro="http://ros.org/wiki/xacro" name="comau">

    <xacro:include filename="materials.xacro"/>

    <link name="base_link">
        <visual>
            <origin xyz="0 0 0" rpy="0 0 0"/>
            <geometry>
                <mesh filename="package://comau_racer5_080_description/meshes/Base.stl" scale="0.001 0.001 0.001"/>
            </geometry>
            <material name="grey"/>
        </visual>
    </link>

    <link name="q1_link">
        <visual>
            <origin xyz="0 0 0.19" rpy="0 0 0"/>
            <geometry>
                <mesh filename="package://comau_racer5_080_description/meshes/Q1.stl" scale="0.001 0.001 0.001"/>
            </geometry>
            <material name="grey"/>
        </visual>
    </link>
    
    <joint name="q1_joint" type="revolute">
        <axis xyz="0 0 1"/>
       <parent link="base_link"/>
       <child link="q1_link"/>
       <limit lower="-2.9671" upper="2.9671" effort="0.0" velocity="6.98131701"/>
    </joint>
    
    <link name="q2_link">
        <visual>
            <origin xyz="0 0 0" rpy="0 0 0"/>
            <geometry>
                <mesh filename="package://comau_racer5_080_description/meshes/Q2.stl" scale="0.001 0.001 0.001"/>
            </geometry>
            <material name="grey"/>
        </visual>
    </link>
    
    <joint name="q2_joint" type="revolute">
       <axis xyz="0 1 0"/>
       <origin xyz="0.050 0.0 0.365"/>
       <parent link="q1_link"/>
       <child link="q2_link"/>
       <limit lower="-1.48352986" upper="2.35619449" effort="0.0" velocity="6.28318531"/>
    </joint>

    <link name="q3_link">
        <visual>
            <origin xyz="0 0 0" rpy="0 0 0"/>
            <geometry>
                <mesh filename="package://comau_racer5_080_description/meshes/Q3.stl" scale="0.001 0.001 0.001"/>
            </geometry>
            <material name="grey"/>
        </visual>
    </link>

    <joint name="q3_joint" type="revolute">
       <axis xyz="0 1 0"/>
       <origin xyz="0 0 0.370"/>
       <parent link="q2_link"/>
       <child link="q3_link"/>
       <limit lower="-2.70526034" upper="1.57079633" effort="0.0" velocity="6.98131701"/>
    </joint>
    

    <link name="q4_link">
        <visual>
            <origin xyz="0 0 0" rpy="0 0 0"/>
            <geometry>
                <mesh filename="package://comau_racer5_080_description/meshes/Q4.stl" scale="0.001 0.001 0.001"/>
            </geometry>
            <material name="grey"/>
        </visual>
    </link>
    
    <joint name="q4_joint" type="revolute">
       <axis xyz="1 0 0"/>
       <origin xyz="0 0 0.050"/>
       <parent link="q3_link"/>
       <child link="q4_link"/>
       <limit lower="-3.4906585" upper="3.4906585" effort="0.0" velocity="8.72664626"/>
    </joint>

    <link name="q5_link">
        <visual>
            <origin xyz="0 0 0" rpy="0 0 0"/>
            <geometry>
                <mesh filename="package://comau_racer5_080_description/meshes/Q5.stl" scale="0.001 0.001 0.001"/>
            </geometry>
            <material name="grey"/>
        </visual>
    </link>

    <joint name="q5_joint" type="revolute">
       <axis xyz="0 1 0"/>
       <origin xyz="0.38594 0 0"/>
       <parent link="q4_link"/>
       <child link="q5_link"/>
       <limit lower="-2.18166156" upper="2.18166156" effort="0.0" velocity="8.72664626"/>
    </joint>

    <link name="q6_link">
        <visual>
            <origin xyz="0 0 0" rpy="0 0 0"/>
            <geometry>
                <mesh filename="package://comau_racer5_080_description/meshes/Q6.stl" scale="0.001 0.001 0.001"/>
            </geometry>
            <material name="grey"/>
        </visual>
    </link>

    <joint name="q6_joint" type="revolute">
       <axis xyz="1 0 0"/>
       <origin xyz="0.080 0 0"/>
       <parent link="q5_link"/>
       <child link="q6_link"/>
       <limit lower="-47.1238898" upper="47.1238898" effort="0.0" velocity="13.962634"/>
    </joint>

</robot>
