<?xml version="1.0" ?>
<robot name="comau_racer5_080"
  xmlns:xacro="http://www.ros.org/wiki/xacro">
  <xacro:property name="package_name" value="comau_racer5_080_description"/>

  <xacro:include filename="$(find ${package_name})/urdf/materials.xacro" />
  <xacro:include filename="$(find ${package_name})/urdf/comau_racer5_080.trans" />
  <xacro:include filename="$(find ${package_name})/urdf/comau_racer5_080.gazebo" />

  <xacro:property name="r2d" value="${pi/180}"/>
  
  <link name="world"></link>

  <link name="base_link">
    <inertial>
      <origin xyz="-0.016692489178242783 5.830304988232292e-05 0.14349325387743003" rpy="0 0 0"/>
      <mass value="8.022239032516847"/>
      <inertia ixx="0.07056" iyy="0.085056" izz="0.055168" ixy="4.9e-05" iyz="6e-06" ixz="-0.006227"/>
    </inertial>
    <visual>
      <origin xyz="0 0 0" rpy="0 0 0"/>
      <geometry>
        <mesh filename="package://${package_name}/meshes/base_link.stl"/>
      </geometry>
      <material name="silver"/>
    </visual>
    <collision>
      <origin xyz="0 0 0" rpy="0 0 0"/>
      <geometry>
        <mesh filename="package://${package_name}/meshes/base_link.stl"/>
      </geometry>
    </collision>
  </link>

  <link name="q1_link_1">
    <inertial>
      <origin xyz="0.037606654842059155 -0.004628236516859879 0.12025910762626352" rpy="0 0 0"/>
      <mass value="7.638878272413433"/>
      <inertia ixx="0.078999" iyy="0.046955" izz="0.062497" ixy="0.000136" iyz="1.9e-05" ixz="-0.00591"/>
    </inertial>
    <visual>
      <origin xyz="-0.0 -0.0 -0.1885" rpy="0 0 0"/>
      <geometry>
        <mesh filename="package://${package_name}/meshes/q1_link_1.stl"/>
      </geometry>
      <material name="silver"/>
    </visual>
    <collision>
      <origin xyz="-0.0 -0.0 -0.1885" rpy="0 0 0"/>
      <geometry>
        <mesh filename="package://${package_name}/meshes/q1_link_1.stl"/>
      </geometry>
    </collision>
  </link>

  <link name="q2_link_1">
    <inertial>
      <origin xyz="-0.010122139068402626 -0.0010609195189776115 0.10601610344187634" rpy="0 0 0"/>
      <mass value="9.757740873886663"/>
      <inertia ixx="0.235859" iyy="0.223176" izz="0.046353" ixy="-9.1e-05" iyz="0.008179" ixz="0.007925"/>
    </inertial>
    <visual>
      <origin xyz="-0.05 0.0005 -0.364" rpy="0 0 0"/>
      <geometry>
        <mesh filename="package://${package_name}/meshes/q2_link_1.stl"/>
      </geometry>
      <material name="silver"/>
    </visual>
    <collision>
      <origin xyz="-0.05 0.0005 -0.364" rpy="0 0 0"/>
      <geometry>
        <mesh filename="package://${package_name}/meshes/q2_link_1.stl"/>
      </geometry>
    </collision>
  </link>

  <link name="q3_link_1">
    <inertial>
      <origin xyz="-0.007324723296943267 -0.007391213542488869 0.017803107927468087" rpy="0 0 0"/>
      <mass value="3.740262261115742"/>
      <inertia ixx="0.008141" iyy="0.009772" izz="0.009099" ixy="2e-06" iyz="-0.000524" ixz="-0.002221"/>
    </inertial>
    <visual>
      <origin xyz="-0.05 0.0005 -0.734" rpy="0 0 0"/>
      <geometry>
        <mesh filename="package://${package_name}/meshes/q3_link_1.stl"/>
      </geometry>
      <material name="silver"/>
    </visual>
    <collision>
      <origin xyz="-0.05 0.0005 -0.734" rpy="0 0 0"/>
      <geometry>
        <mesh filename="package://${package_name}/meshes/q3_link_1.stl"/>
      </geometry>
    </collision>
  </link>

  <link name="q4_link_1">
    <inertial>
      <origin xyz="0.2353593069196668 0.0 0.0" rpy="0 0 0"/>
      <mass value="1.7488722435466972"/>
      <inertia ixx="0.004495" iyy="0.030823" izz="0.03138" ixy="0.0" iyz="0.0" ixz="0.0"/>
    </inertial>
    <visual>
      <origin xyz="-0.0905 0.0005 -0.783998" rpy="0 0 0"/>
      <geometry>
        <mesh filename="package://${package_name}/meshes/q4_link_1.stl"/>
      </geometry>
      <material name="silver"/>
    </visual>
    <collision>
      <origin xyz="-0.0905 0.0005 -0.783998" rpy="0 0 0"/>
      <geometry>
        <mesh filename="package://${package_name}/meshes/q4_link_1.stl"/>
      </geometry>
    </collision>
  </link>

  <link name="q5_link_1">
    <inertial>
      <origin xyz="0.027292159537539107 0.0013712897030821692 -5.1641371843214046e-06" rpy="0 0 0"/>
      <mass value="0.5620704849356615"/>
      <inertia ixx="0.000551" iyy="0.001042" izz="0.001076" ixy="0.0" iyz="0.0" ixz="-0.0"/>
    </inertial>
    <visual>
      <origin xyz="-0.4355 0.0005 -0.783998" rpy="0 0 0"/>
      <geometry>
        <mesh filename="package://${package_name}/meshes/q5_link_1.stl"/>
      </geometry>
      <material name="silver"/>
    </visual>
    <collision>
      <origin xyz="-0.4355 0.0005 -0.783998" rpy="0 0 0"/>
      <geometry>
        <mesh filename="package://${package_name}/meshes/q5_link_1.stl"/>
      </geometry>
    </collision>
  </link>

  <link name="q6_link_1">
    <inertial>
      <origin xyz="0.0040723327362690576 -2.0433994003433856e-06 -0.00012905570870358485" rpy="0 0 0"/>
      <mass value="0.0220357559368793"/>
      <inertia ixx="3e-06" iyy="2e-06" izz="2e-06" ixy="0.0" iyz="0.0" ixz="0.0"/>
    </inertial>
    <visual>
      <origin xyz="-0.5065 0.0005 -0.783998" rpy="0 0 0"/>
      <geometry>
        <mesh filename="package://${package_name}/meshes/q6_link_1.stl"/>
      </geometry>
      <material name="silver"/>
    </visual>
    <collision>
      <origin xyz="-0.5065 0.0005 -0.783998" rpy="0 0 0"/>
      <geometry>
        <mesh filename="package://${package_name}/meshes/q6_link_1.stl"/>
      </geometry>
    </collision>
  </link>
  
  <joint name="base_joint" type="fixed">
      <origin xyz="0 0 0" rpy="0 0 0"/>
      <parent link="world"/>
      <child link="base_link"/>        
  </joint>

  <joint name="q1_joint" type="revolute">
    <origin xyz="0.0 0.0 0.1885" rpy="0 0 0"/>
    <parent link="base_link"/>
    <child link="q1_link_1"/>
    <axis xyz="-0.0 -0.0 -1.0"/>
    <limit lower="-${r2d*170}" upper="${r2d*170}" effort="0.0" velocity="${r2d*400}"/>
    <dynamics damping="0.001" friction="0.001"/>
  </joint>

  <joint name="q2_joint" type="revolute">
    <origin xyz="0.05 -0.0005 0.1755" rpy="0 0 0"/>
    <parent link="q1_link_1"/>
    <child link="q2_link_1"/>
    <axis xyz="0.0 1.0 -0.0"/>
    <limit lower="-${r2d*85}" upper="${r2d*135}" effort="0.0" velocity="${r2d*360}"/>
    <dynamics damping="0.001" friction="0.001"/>
  </joint>

  <joint name="q3_joint" type="revolute">
    <origin xyz="0.0 0.0 0.37" rpy="0 0 0"/>
    <parent link="q2_link_1"/>
    <child link="q3_link_1"/>
    <axis xyz="-0.0 1.0 -0.0"/>
    <limit lower="-${r2d*155}" upper="${r2d*90}" effort="0.0" velocity="${r2d*400}"/>
    <dynamics damping="0.001" friction="0.001"/>
  </joint>

  <joint name="q4_joint" type="revolute">
    <origin xyz="0.0405 0.0 0.049998" rpy="0 0 0"/>
    <parent link="q3_link_1"/>
    <child link="q4_link_1"/>
    <axis xyz="1.0 0.0 0.0"/>
    <limit lower="-${r2d*200}" upper="${r2d*200}" effort="0.0" velocity="${r2d*500}"/>
    <dynamics damping="0.001" friction="0.001"/>
  </joint>

  <joint name="q5_joint" type="revolute">
    <origin xyz="0.345 0.0 0.0" rpy="0 0 0"/>
    <parent link="q4_link_1"/>
    <child link="q5_link_1"/>
    <axis xyz="0.0 1.0 -0.0"/>
    <limit lower="-${r2d*125}" upper="${r2d*125}" effort="0.0" velocity="${r2d*500}"/>
    <dynamics damping="0.001" friction="0.001"/>
  </joint>

  <joint name="q6_joint" type="revolute">
    <origin xyz="0.071 0.0 0.0" rpy="0 0 0"/>
    <parent link="q5_link_1"/>
    <child link="q6_link_1"/>
    <axis xyz="1.0 -0.0 0.0"/>
    <limit lower="-${r2d*2700}" upper="${r2d*2700}" effort="0.0" velocity="${r2d*800}"/>
    <dynamics damping="0.001" friction="0.001"/>
  </joint>

  <!-- <gazebo reference="base_link">
    <material>Gazebo/Grey</material>
  </gazebo>
  
  <gazebo reference="q1_link_1">
    <material>Gazebo/Grey</material>
  </gazebo>

  <gazebo reference="q2_link_1">
    <material>Gazebo/Grey</material>
  </gazebo>

  <gazebo reference="q3_link_1">
    <material>Gazebo/Grey</material>
  </gazebo>

  <gazebo reference="q4_link_1">
    <material>Gazebo/Grey</material>
  </gazebo>

  <gazebo reference="q5_link_1">
    <material>Gazebo/Grey</material>
  </gazebo>
  
  <gazebo reference="q6_link_1">
    <material>Gazebo/Grey</material>
  </gazebo> -->

  <!-- <gazebo>
    <plugin name="gazebo_ros_joint_state_publisher" filename="libgazebo_ros_joint_state_publisher.so">
      <update_rate>20</update_rate>
      <joint_name>q1_joint</joint_name>
      <joint_name>q2_joint</joint_name>
      <joint_name>q3_joint</joint_name>
      <joint_name>q4_joint</joint_name>
      <joint_name>q5_joint</joint_name>
      <joint_name>q6_joint</joint_name>
    </plugin>
  </gazebo>-->
  
  <!-- <ros2_control name="GazeboSystem" type="system">
    <hardware>
      <plugin>gazebo_ros2_control/GazeboSystem</plugin>
    </hardware>
    <joint name="q1_joint">
      <command_interface name="position"/>
      <state_interface name="position">
        <param name="initial_value">0.0</param>
      </state_interface>
      <state_interface name="velocity"/>
    </joint>
    <joint name="q2_joint">
      <command_interface name="position"/>
      <state_interface name="position">
        <param name="initial_value">0.0</param>
      </state_interface>
      <state_interface name="velocity"/>
    </joint>
    <joint name="q3_joint">
      <command_interface name="position"/>
      <state_interface name="position">
        <param name="initial_value">0.0</param>
      </state_interface>
      <state_interface name="velocity"/>
    </joint>
    <joint name="q4_joint">
      <command_interface name="position"/>
      <state_interface name="position">
        <param name="initial_value">0.0</param>
      </state_interface>
      <state_interface name="velocity"/>
    </joint>
    <joint name="q5_joint">
      <command_interface name="position"/>
      <state_interface name="position">
        <param name="initial_value">0.0</param>
      </state_interface>
      <state_interface name="velocity"/>
    </joint>
    <joint name="q6_joint">
      <command_interface name="position"/>
      <state_interface name="position">
        <param name="initial_value">0.0</param>
      </state_interface>
      <state_interface name="velocity"/>
    </joint>
  </ros2_control> -->
  <!-- <gazebo>
    <plugin name="gazebo_ros2_control" filename="libgazebo_ros2_control.so">
      <parameters>$(find ${package_name})/config/comau_racer5_080_controllers.yaml</parameters>
    </plugin>
  </gazebo>  -->

  <!-- This plugin will read a JointTrajectory message from the /set_joint_trajectory topic 
        and move the machine accordingly. It's a bit clunky but it works. -->
  <!-- You'll probably want to add damping to the joints to stop them it flopping around. 
        e.g. <dynamics damping="10.0" friction="10.0"/> -->
  <!-- Here's an example message to publish to test it:
        ros2 topic pub -1 /set_joint_trajectory trajectory_msgs/msg/JointTrajectory  '{header: {frame_id: world}, joint_names: [slider_joint, arm_joint], points: [  {positions: {0.8,0.6}} ]}' -->
  <!-- <gazebo>
    <plugin name="gazebo_ros_joint_pose_trajectory" filename="libgazebo_ros_joint_pose_trajectory.so">
      <update_rate>2</update_rate>
    </plugin>
  </gazebo> -->

</robot>
